+ source /root/mugen-riscv/libs/locallibs/common_lib.sh
++ python3 --version
++ '[' 0 -eq 0 ']'
++ source /root/mugen-riscv/libs/locallibs/common_lib_python.sh
+ main
++ type -t post_test
+ '[' -n function ']'
+ trap post_test EXIT INT HUP TERM
+ rpm -qa
+ grep expect
++ type -t config_params
+ '[' -n '' ']'
++ type -t pre_test
+ '[' -n function ']'
+ pre_test
+ LOG_INFO 'Start to prepare the test environment.'
+ message='Start to prepare the test environment.'
+ python3 /root/mugen-riscv/libs/locallibs/mugen_log.py --level info --message 'Start to prepare the test environment.'
Wed Sep 13 11:01:21 2023 - INFO  - Start to prepare the test environment.
+ DNF_INSTALL 'powertop tuned'
+ pkgs='powertop tuned'
+ node=1
+ '[' -z '' ']'
+ tmpfile=
++ python3 /root/mugen-riscv/libs/locallibs/rpm_manage.py install --pkgs 'powertop tuned' --node 1 --tempfile ''
Wed Sep 13 11:01:30 2023 - INFO  - pkgs:(powertop tuned) is already installed
+ tmpfile2=
+ '[' -z '' ']'
+ tmpfile=
+ LOG_INFO 'End to prepare the test environment.'
+ message='End to prepare the test environment.'
+ python3 /root/mugen-riscv/libs/locallibs/mugen_log.py --level info --message 'End to prepare the test environment.'
Wed Sep 13 11:01:31 2023 - INFO  - End to prepare the test environment.
++ type -t run_test
+ '[' -n function ']'
+ run_test
+ LOG_INFO 'Start to run test.'
+ message='Start to run test.'
+ python3 /root/mugen-riscv/libs/locallibs/mugen_log.py --level info --message 'Start to run test.'
Wed Sep 13 11:01:31 2023 - INFO  - Start to run test.
+ powertop2tuned new_profile_name --force
Traceback (most recent call last):
  File "/usr/lib/python3.11/site-packages/tuned/utils/global_config.py", line 44, in load_config
    with open(file_name) as f:
         ^^^^^^^^^^^^^^^
FileNotFoundError: [Errno 2] No such file or directory: '/etc/tuned/tuned-main.conf'

During handling of the above exception, another exception occurred:

Traceback (most recent call last):
  File "/usr/sbin/tuned-adm", line 50, in <module>
    config = GlobalConfig()
             ^^^^^^^^^^^^^^
  File "/usr/lib/python3.11/site-packages/tuned/utils/global_config.py", line 15, in __init__
    self.load_config(file_name=config_file)
  File "/usr/lib/python3.11/site-packages/tuned/utils/global_config.py", line 59, in load_config
    raise TunedException("Global TuneD configuration file '%s' not found." % file_name)
tuned.exceptions.TunedException: Global TuneD configuration file '/etc/tuned/tuned-main.conf' not found.
Running PowerTOP, please wait...
Generating shell script /etc/tuned/new_profile_name/script.sh
Generating TuneD config file /etc/tuned/new_profile_name/tuned.conf
+ CHECK_RESULT 0
+ actual_result=0
+ expect_result=0
+ mode=0
+ error_log=
+ '[' -z 0 ']'
+ '[' 0 -eq 0 ']'
+ test 0x '!=' 0x
+ return 0
+ tuned-adm profile new_profile_name
Traceback (most recent call last):
  File "/usr/lib/python3.11/site-packages/tuned/utils/global_config.py", line 44, in load_config
    with open(file_name) as f:
         ^^^^^^^^^^^^^^^
FileNotFoundError: [Errno 2] No such file or directory: '/etc/tuned/tuned-main.conf'

During handling of the above exception, another exception occurred:

Traceback (most recent call last):
  File "/usr/sbin/tuned-adm", line 50, in <module>
    config = GlobalConfig()
             ^^^^^^^^^^^^^^
  File "/usr/lib/python3.11/site-packages/tuned/utils/global_config.py", line 15, in __init__
    self.load_config(file_name=config_file)
  File "/usr/lib/python3.11/site-packages/tuned/utils/global_config.py", line 59, in load_config
    raise TunedException("Global TuneD configuration file '%s' not found." % file_name)
tuned.exceptions.TunedException: Global TuneD configuration file '/etc/tuned/tuned-main.conf' not found.
+ CHECK_RESULT 1
+ actual_result=1
+ expect_result=0
+ mode=0
+ error_log=
+ '[' -z 1 ']'
+ '[' 0 -eq 0 ']'
+ test 1x '!=' 0x
+ test -n ''
+ (( exec_result++ ))
+ LOG_ERROR 'oe_test_power_powertop2tuned_optimize.sh line 32'
+ message='oe_test_power_powertop2tuned_optimize.sh line 32'
+ python3 /root/mugen-riscv/libs/locallibs/mugen_log.py --level error --message 'oe_test_power_powertop2tuned_optimize.sh line 32'
Wed Sep 13 11:01:38 2023 - ERROR - oe_test_power_powertop2tuned_optimize.sh line 32
+ return 0
+ LOG_INFO 'End to run test.'
+ message='End to run test.'
+ python3 /root/mugen-riscv/libs/locallibs/mugen_log.py --level info --message 'End to run test.'
Wed Sep 13 11:01:39 2023 - INFO  - End to run test.
+ CASE_RESULT 0
+ case_re=0
+ test -z 1
+ test 1 -gt 0
+ LOG_ERROR 'failed to execute the case.'
+ message='failed to execute the case.'
+ python3 /root/mugen-riscv/libs/locallibs/mugen_log.py --level error --message 'failed to execute the case.'
Wed Sep 13 11:01:39 2023 - ERROR - failed to execute the case.
+ exit 1
+ post_test
+ LOG_INFO 'Start to restore the test environment.'
+ message='Start to restore the test environment.'
+ python3 /root/mugen-riscv/libs/locallibs/mugen_log.py --level info --message 'Start to restore the test environment.'
Wed Sep 13 11:01:40 2023 - INFO  - Start to restore the test environment.
+ DNF_REMOVE
+ node=1
+ pkg_list=
+ mode=0
+ [[ -z '' ]]
+ [[ -z '' ]]
+ LOG_WARN 'no thing to do.'
+ message='no thing to do.'
+ python3 /root/mugen-riscv/libs/locallibs/mugen_log.py --level warn --message 'no thing to do.'
Wed Sep 13 11:01:40 2023 - WARN  - no thing to do.
+ return 0
+ LOG_INFO 'End to restore the test environment.'
+ message='End to restore the test environment.'
+ python3 /root/mugen-riscv/libs/locallibs/mugen_log.py --level info --message 'End to restore the test environment.'
Wed Sep 13 11:01:41 2023 - INFO  - End to restore the test environment.
